Workbook

Sheet Сводка
A1: Сводка сметы
A2: Дом 596,6 м² по наружному контуру (отапливаемая 561 м²) — редакция П1.2 + благоустройство 1 200 м²
A4: Параметр | B4: Значение
A5: Площадь дома по наружному контуру, м² | B5: 596.6
A6: Отапливаемая площадь, м² | B6: 561
A7: Генподряд / управление стройкой, % | B7: 0.08
A8: Резерв на непредвиденное, % | B8: 0.08
A10: Раздел | B10: Мин, ₽ | C10: База, ₽ | D10: Макс, ₽ | E10: Доля базы
A11: 0. Изыскания и проект | B11: =SUMIF(Смета!$B$4:$B$118,$A11,Смета!$J$4:$J$118) -> 2566436 | C11: =SUMIF(Смета!$B$4:$B$118,$A11,Смета!$G$4:$G$118) -> 3222420 | D11: =SUMIF(Смета!$B$4:$B$118,$A11,Смета!$K$4:$K$118) -> 4690130 | E11: =C11/$C$22 -> 0.032932727
A12: 1. Подготовка участка | B12: =SUMIF(Смета!$B$4:$B$118,$A12,Смета!$J$4:$J$118) -> 1072285 | C12: =SUMIF(Смета!$B$4:$B$118,$A12,Смета!$G$4:$G$118) -> 1309100 | D12: =SUMIF(Смета!$B$4:$B$118,$A12,Смета!$K$4:$K$118) -> 1780340 | E12: =C12/$C$22 -> 0.013378837
A13: 2. Фундамент, цоколь, чаша бассейна | B13: =SUMIF(Смета!$B$4:$B$118,$A13,Смета!$J$4:$J$118) -> 9609450 | C13: =SUMIF(Смета!$B$4:$B$118,$A13,Смета!$G$4:$G$118) -> 10775500 | D13: =SUMIF(Смета!$B$4:$B$118,$A13,Смета!$K$4:$K$118) -> 13579600 | E13: =C13/$C$22 -> 0.11012425
A14: 3. Коробка, кровля, фасад, окна | B14: =SUMIF(Смета!$B$4:$B$118,$A14,Смета!$J$4:$J$118) -> 22587336 | C14: =SUMIF(Смета!$B$4:$B$118,$A14,Смета!$G$4:$G$118) -> 26165040 | D14: =SUMIF(Смета!$B$4:$B$118,$A14,Смета!$K$4:$K$118) -> 33268298 | E14: =C14/$C$22 -> 0.26740342
A15: 4. Инженерные системы дома | B15: =SUMIF(Смета!$B$4:$B$118,$A15,Смета!$J$4:$J$118) -> 15860830 | C15: =SUMIF(Смета!$B$4:$B$118,$A15,Смета!$G$4:$G$118) -> 19649800 | D15: =SUMIF(Смета!$B$4:$B$118,$A15,Смета!$K$4:$K$118) -> 26844240 | E15: =C15/$C$22 -> 0.20081848
A16: 5. SPA и бассейн | B16: =SUMIF(Смета!$B$4:$B$118,$A16,Смета!$J$4:$J$118) -> 3019000 | C16: =SUMIF(Смета!$B$4:$B$118,$A16,Смета!$G$4:$G$118) -> 3830000 | D16: =SUMIF(Смета!$B$4:$B$118,$A16,Смета!$K$4:$K$118) -> 5504000 | E16: =C16/$C$22 -> 0.039142118
A17: 6. Внутренняя отделка | B17: =SUMIF(Смета!$B$4:$B$118,$A17,Смета!$J$4:$J$118) -> 9164450 | C17: =SUMIF(Смета!$B$4:$B$118,$A17,Смета!$G$4:$G$118) -> 11609000 | D17: =SUMIF(Смета!$B$4:$B$118,$A17,Смета!$K$4:$K$118) -> 17175280 | E17: =C17/$C$22 -> 0.11864252
A18: 7. Кухня и встроенная мебель | B18: =SUMIF(Смета!$B$4:$B$118,$A18,Смета!$J$4:$J$118) -> 3541000 | C18: =SUMIF(Смета!$B$4:$B$118,$A18,Смета!$G$4:$G$118) -> 4860000 | D18: =SUMIF(Смета!$B$4:$B$118,$A18,Смета!$K$4:$K$118) -> 7958000 | E18: =C18/$C$22 -> 0.049668588
A19: 8. Наружные сети и подключения | B19: =SUMIF(Смета!$B$4:$B$118,$A19,Смета!$J$4:$J$118) -> 2371793 | C19: =SUMIF(Смета!$B$4:$B$118,$A19,Смета!$G$4:$G$118) -> 3101393 | D19: =SUMIF(Смета!$B$4:$B$118,$A19,Смета!$K$4:$K$118) -> 4421693 | E19: =C19/$C$22 -> 0.031695846
A20: 9. Благоустройство | B20: =SUMIF(Смета!$B$4:$B$118,$A20,Смета!$J$4:$J$118) -> 9850638.5 | C20: =SUMIF(Смета!$B$4:$B$118,$A20,Смета!$G$4:$G$118) -> 12746310 | D20: =SUMIF(Смета!$B$4:$B$118,$A20,Смета!$K$4:$K$118) -> 18333653 | E20: =C20/$C$22 -> 0.13026568
A21: 10. Прочие затраты стройки | B21: =SUMIF(Смета!$B$4:$B$118,$A21,Смета!$J$4:$J$118) -> 464000 | C21: =SUMIF(Смета!$B$4:$B$118,$A21,Смета!$G$4:$G$118) -> 580000 | D21: =SUMIF(Смета!$B$4:$B$118,$A21,Смета!$K$4:$K$118) -> 842000 | E21: =C21/$C$22 -> 0.005927527
A22: Итого прямые затраты | B22: =SUM(B11:B21) -> 80107218 | C22: =SUM(C11:C21) -> 97848563 | D22: =SUM(D11:D21) -> 134397234
A23: Генподряд / управление | B23: =B22*$B$7 -> 6408577.5 | C23: =C22*$B$7 -> 7827885 | D23: =D22*$B$7 -> 10751779
A24: Резерв на непредвиденное | B24: =(B22+B23)*$B$8 -> 6921263.7 | C24: =(C22+C23)*$B$8 -> 8454115.8 | D24: =(D22+D23)*$B$8 -> 11611921
A25: ВСЕГО ПО ПРОЕКТУ | B25: =SUM(B22:B24) -> 93437060 | C25: =SUM(C22:C24) -> 1.1413056e+08 | D25: =SUM(D22:D24) -> 1.5676093e+08
A26: На 1 м² дома (всё, вкл. участок) | B26: =B25/$B$5 -> 156615.92 | C26: =C25/$B$5 -> 191301.65 | D26: =D25/$B$5 -> 262757.18
A28: Не входит: мебель (кроме кухни и встроенной), шторы, ТВ и аудио, декор, ландшафт сверх списка, стоимость земли, кредит.
A29: Сценарий отопления — магистральный газ. Если газа нет — лист «Опции», строка «Тепловой насос».
A30: Цены — средний рынок Москвы и МО на IV кв. 2026 (материалы + работы). Перед тендером пересчитать по рабочему проекту и 3 КП.
A31: Ориентир рынка: средняя стоимость ИЖС в МО в 2026 г. — 113 тыс. ₽/м² (Noco/ТАСС, май 2026); дом этого класса с SPA закономерно выше.

Sheet Смета
A1: Укрупнённая смета — редакция П1.2 — дом и участок, Тверитино (КН 50:32:0030118:1930). Цены Москва/МО, IV кв. 2026, материалы + работы, без НДС подрядчиков-ИП
A2: Синие цифры — исходные данные (можно менять), чёрные — формулы. К мин / К макс — диапазон по рынку для позиции.
A3: № | B3: Раздел | C3: Наименование работ и затрат | D3: Ед. | E3: Кол-во | F3: Цена база, ₽ | G3: Сумма база, ₽ | H3: К мин | I3: К макс | J3: Сумма мин, ₽ | K3: Сумма макс, ₽ | L3: Основание / примечание
A4: 0. Изыскания и проект
A5: 0.1 | B5: 0. Изыскания и проект | C5: Топосъёмка 1:500 с подземными коммуникациями | D5: компл | E5: 1 | F5: 35000 | G5: =E5*F5 -> 35000 | H5: 0.85 | I5: 1.3 | J5: =G5*H5 -> 29750 | K5: =G5*I5 -> 45500 | L5: Привязать СТП/ВЛ 10 кВ и охранные зоны
A6: 0.2 | B6: 0. Изыскания и проект | C6: Инженерно-геологические изыскания (3 скважины 8–10 м, лаборатория) | D6: компл | E6: 1 | F6: 95000 | G6: =E6*F6 -> 95000 | H6: 0.85 | I6: 1.4 | J6: =G6*H6 -> 80750 | K6: =G6*I6 -> 133000 | L6: Обязательно до проекта цоколя и бассейна
A7: 0.3 | B7: 0. Изыскания и проект | C7: Архитектурный и конструктивный проект (АР, КР, рабочка) | D7: м² | E7: 596.6 | F7: 2200 | G7: =E7*F7 -> 1312520 | H7: 0.8 | I7: 1.5 | J7: =G7*H7 -> 1050016 | K7: =G7*I7 -> 1968780 | L7: Площадь по наружному контуру
A8: 0.4 | B8: 0. Изыскания и проект | C8: Проекты инженерных систем (ОВиК, ВК, ЭОМ, СС, бассейн, автоматика) | D8: м² | E8: 596.6 | F8: 1500 | G8: =E8*F8 -> 894900 | H8: 0.8 | I8: 1.5 | J8: =G8*H8 -> 715920 | K8: =G8*I8 -> 1342350
A9: 0.5 | B9: 0. Изыскания и проект | C9: Ландшафтный проект + дендроплан: что сохраняем, что и куда пересаживаем | D9: компл | E9: 1 | F9: 180000 | G9: =E9*F9 -> 180000 | H9: 0.7 | I9: 1.5 | J9: =G9*H9 -> 126000 | K9: =G9*I9 -> 270000
A10: 0.6 | B10: 0. Изыскания и проект | C10: Анализ поверхностного стока и проект ливневого водоотвода | D10: компл | E10: 1 | F10: 70000 | G10: =E10*F10 -> 70000 | H10: 0.8 | I10: 1.4 | J10: =G10*H10 -> 56000 | K10: =G10*I10 -> 98000 | L10: До благоустройства
A11: 0.7 | B11: 0. Изыскания и проект | C11: Обследование колодца: дебит, химический и бак. анализ, ТВ-осмотр | D11: компл | E11: 1 | F11: 35000 | G11: =E11*F11 -> 35000 | H11: 0.8 | I11: 1.5 | J11: =G11*H11 -> 28000 | K11: =G11*I11 -> 52500 | L11: Решение: колодец / скважина / оба
A12: 0.8 | B12: 0. Изыскания и проект | C12: Технический надзор за стройкой (12 мес.) | D12: мес | E12: 12 | F12: 45000 | G12: =E12*F12 -> 540000 | H12: 0.8 | I12: 1.3 | J12: =G12*H12 -> 432000 | K12: =G12*I12 -> 702000
A13: 0.9 | B13: 0. Изыскания и проект | C13: Геодезическая разбивка и исполнительные съёмки | D13: компл | E13: 1 | F13: 60000 | G13: =E13*F13 -> 60000 | H13: 0.8 | I13: 1.3 | J13: =G13*H13 -> 48000 | K13: =G13*I13 -> 78000
A14: 1. Подготовка участка
A15: 1.1 | B15: 1. Подготовка участка | C15: Срезка растительного слоя, планировка пятна застройки | D15: м² | E15: 520 | F15: 450 | G15: =E15*F15 -> 234000 | H15: 0.8 | I15: 1.3 | J15: =G15*H15 -> 187200 | K15: =G15*I15 -> 304200
A16: 1.2 | B16: 1. Подготовка участка | C16: Разработка котлована цоколя и вывоз грунта | D16: м³ | E16: 477 | F16: 1300 | G16: =E16*F16 -> 620100 | H16: 0.85 | I16: 1.4 | J16: =G16*H16 -> 527085 | K16: =G16*I16 -> 868140 | L16: Котлован ~9×11×3,2 м + корыто плиты
A17: 1.3 | B17: 1. Подготовка участка | C17: Временные сооружения, электричество и вода стройки, бытовка | D17: компл | E17: 1 | F17: 350000 | G17: =E17*F17 -> 350000 | H17: 0.8 | I17: 1.3 | J17: =G17*H17 -> 280000 | K17: =G17*I17 -> 455000
A18: 1.4 | B18: 1. Подготовка участка | C18: Пересадка розария, 6 шаровидных туй и мешающих деревьев | D18: компл | E18: 1 | F18: 60000 | G18: =E18*F18 -> 60000 | H18: 0.7 | I18: 1.5 | J18: =G18*H18 -> 42000 | K18: =G18*I18 -> 90000 | L18: По дендроплану
A19: 1.5 | B19: 1. Подготовка участка | C19: Временная защита туй и деревьев на время стройки | D19: компл | E19: 1 | F19: 45000 | G19: =E19*F19 -> 45000 | H19: 0.8 | I19: 1.4 | J19: =G19*H19 -> 36000 | K19: =G19*I19 -> 63000
A20: 2. Фундамент, цоколь, чаша бассейна
A21: 2.1 | B21: 2. Фундамент, цоколь, чаша бассейна | C21: Монолитная утеплённая плита 300 мм (подушка, ЭППС 100, гидроизоляция, B25) | D21: м² | E21: 266.6 | F21: 17500 | G21: =E21*F21 -> 4665500 | H21: 0.9 | I21: 1.2 | J21: =G21*H21 -> 4198950 | K21: =G21*I21 -> 5598600 | L21: Под 1 этажом без цоколя
A22: 2.2 | B22: 2. Фундамент, цоколь, чаша бассейна | C22: Цоколь: монолитные стены 250 мм и плита, 2-слойная гидроизоляция, ЭППС, пристенный дренаж | D22: м² цоколя | E22: 80 | F22: 60000 | G22: =E22*F22 -> 4800000 | H22: 0.9 | I22: 1.3 | J22: =G22*H22 -> 4320000 | K22: =G22*I22 -> 6240000 | L22: Цена зависит от УГВ — геология
A23: 2.3 | B23: 2. Фундамент, цоколь, чаша бассейна | C23: Монолитная чаша бассейна 4,0×2,5×1,4 м (B30 W8, гидрошпонки, закладные) | D23: компл | E23: 1 | F23: 850000 | G23: =E23*F23 -> 850000 | H23: 0.85 | I23: 1.3 | J23: =G23*H23 -> 722500 | K23: =G23*I23 -> 1105000
A24: 2.4 | B24: 2. Фундамент, цоколь, чаша бассейна | C24: Приямок и шахта малого грузового подъёмника | D24: компл | E24: 1 | F24: 80000 | G24: =E24*F24 -> 80000 | H24: 0.8 | I24: 1.3 | J24: =G24*H24 -> 64000 | K24: =G24*I24 -> 104000
A25: 2.5 | B25: 2. Фундамент, цоколь, чаша бассейна | C25: Наружный хозвход в цоколь: приямок, лестница, утеплённая дверь, водоотвод | D25: компл | E25: 1 | F25: 380000 | G25: =E25*F25 -> 380000 | H25: 0.8 | I25: 1.4 | J25: =G25*H25 -> 304000 | K25: =G25*I25 -> 532000 | L25: Со стороны гаража
A26: 3. Коробка, кровля, фасад, окна
A27: 3.1 | B27: 3. Коробка, кровля, фасад, окна | C27: Наружные стены — газобетон D500 400 мм (кладка, армирование, армопояса, перемычки) | D27: м² | E27: 522.7 | F27: 6800 | G27: =E27*F27 -> 3554360 | H27: 0.9 | I27: 1.2 | J27: =G27*H27 -> 3198924 | K27: =G27*I27 -> 4265232 | L27: Площадь стен по контуру минус ничего (запас)
A28: 3.2 | B28: 3. Коробка, кровля, фасад, окна | C28: Внутренние несущие стены и перегородки (газобетон 150–300, кирпич в мокрых зонах) | D28: м² | E28: 445 | F28: 3600 | G28: =E28*F28 -> 1602000 | H28: 0.85 | I28: 1.25 | J28: =G28*H28 -> 1361700 | K28: =G28*I28 -> 2002500
A29: 3.3 | B29: 3. Коробка, кровля, фасад, окна | C29: Акустические доп. обшивки: кабинет, спальни, игровая, стена SPA–холл | D29: м² | E29: 140 | F29: 4200 | G29: =E29*F29 -> 588000 | H29: 0.85 | I29: 1.3 | J29: =G29*H29 -> 499800 | K29: =G29*I29 -> 764400 | L29: 2×ГКЛ на независимом каркасе + минвата
A30: 3.4 | B30: 3. Коробка, кровля, фасад, окна | C30: Монолитные перекрытия 200 мм (над цоколем, 1 и 2 этажом, SPA, гаражом) | D30: м² | E30: 596.6 | F30: 9800 | G30: =E30*F30 -> 5846680 | H30: 0.9 | I30: 1.2 | J30: =G30*H30 -> 5262012 | K30: =G30*I30 -> 7016016
A31: 3.5 | B31: 3. Коробка, кровля, фасад, окна | C31: Усиление перекрытия гаража: закладные под подъёмники, балка под стену 2 этажа | D31: компл | E31: 1 | F31: 280000 | G31: =E31*F31 -> 280000 | H31: 0.8 | I31: 1.4 | J31: =G31*H31 -> 224000 | K31: =G31*I31 -> 392000
A32: 3.6 | B32: 3. Коробка, кровля, фасад, окна | C32: Монолитная П-образная лестница + марш в цоколь (каркас) | D32: компл | E32: 1 | F32: 420000 | G32: =E32*F32 -> 420000 | H32: 0.85 | I32: 1.3 | J32: =G32*H32 -> 357000 | K32: =G32*I32 -> 546000
A33: 3.7 | B33: 3. Коробка, кровля, фасад, окна | C33: Кровля: стропила, утепление 250 мм, мембраны, фальц 0,6–0,7 мм, снегозадержатели 2 ряда, водосток с обогревом | D33: м² | E33: 426 | F33: 12500 | G33: =E33*F33 -> 5325000 | H33: 0.85 | I33: 1.25 | J33: =G33*H33 -> 4526250 | K33: =G33*I33 -> 6656250 | L33: Вальма 20° + два ската 10°
A34: 3.8 | B34: 3. Коробка, кровля, фасад, окна | C34: Фасад: утепление 50 мм + облицовочный кирпич / вентфасад с планкеном | D34: м² | E34: 410 | F34: 8800 | G34: =E34*F34 -> 3608000 | H34: 0.85 | I34: 1.35 | J34: =G34*H34 -> 3066800 | K34: =G34*I34 -> 4870800
A35: 3.9 | B35: 3. Коробка, кровля, фасад, окна | C35: Окна ПВХ/алюм-дерево, 3-камерный стеклопакет, тёплый монтаж | D35: м² | E35: 44 | F35: 24000 | G35: =E35*F35 -> 1056000 | H35: 0.85 | I35: 1.4 | J35: =G35*H35 -> 897600 | K35: =G35*I35 -> 1478400
A36: 3.10 | B36: 3. Коробка, кровля, фасад, окна | C36: Панорамное остекление: тёплый алюминий, HS-порталы, солнцезащитное стекло | D36: м² | E36: 38 | F36: 58000 | G36: =E36*F36 -> 2204000 | H36: 0.85 | I36: 1.35 | J36: =G36*H36 -> 1873400 | K36: =G36*I36 -> 2975400 | L36: Гостиная + SPA
A37: 3.11 | B37: 3. Коробка, кровля, фасад, окна | C37: Секционные ворота гаража 3,0×2,75 м, утеплённые, с приводом | D37: шт | E37: 2 | F37: 320000 | G37: =E37*F37 -> 640000 | H37: 0.8 | I37: 1.3 | J37: =G37*H37 -> 512000 | K37: =G37*I37 -> 832000
A38: 3.12 | B38: 3. Коробка, кровля, фасад, окна | C38: Входная дверь с терморазрывом | D38: шт | E38: 1 | F38: 380000 | G38: =E38*F38 -> 380000 | H38: 0.7 | I38: 1.5 | J38: =G38*H38 -> 266000 | K38: =G38*I38 -> 570000
A39: 3.13 | B39: 3. Коробка, кровля, фасад, окна | C39: Наружные технические двери (SPA, хозблок, котельная, гараж) | D39: шт | E39: 4 | F39: 55000 | G39: =E39*F39 -> 220000 | H39: 0.8 | I39: 1.4 | J39: =G39*H39 -> 176000 | K39: =G39*I39 -> 308000
A40: 3.14 | B40: 3. Коробка, кровля, фасад, окна | C40: Утеплённая отмостка | D40: м² | E40: 58 | F40: 4500 | G40: =E40*F40 -> 261000 | H40: 0.85 | I40: 1.3 | J40: =G40*H40 -> 221850 | K40: =G40*I40 -> 339300
...

Sheet Опции
A1: Опции и альтернативы (не входят в итог) | B1: Δ к бюджету, ₽ | C1: Комментарий
A2: Тепловой насос воздух–вода ~30 кВт вместо газа (минус газ на участке 450 000) | B2: 2100000 | C2: Плюс к мощности ещё ~10 кВт
A3: Снеготаяние площадки въезда №1 (43,8 м²) | B3: 350000 | C3: Ворота гаража смотрят на север-восток, там дольше лежит снег
A4: Стеклянная перегородка между бассейном и лаунжем SPA | B4: 420000 | C4: Сухой и прохладный лаунж; меньше нагрузка на осушитель
A5: Системный дренаж участка — если покажут топосъёмка и геология | B5: 650000 | C5: Пристенный дренаж уже в смете
A6: Дровяной камин с дымоходом в SPA вместо электрокамина | B6: 520000
A7: Солнечные панели 10 кВт на кровле гаража | B7: 1100000
A8: Встроенная мультирум-аудиосистема | B8: 650000 | C8: Трассы уже заложены в смете
A9: Подогрев купели тепловым насосом вместо ТЭНа | B9: 180000 | C9: Дешевле в эксплуатации
A10: Солнцезащитные внешние ламели на юго-западный фасад | B10: 480000 | C10: Снижает перегрев гостиной

Sheet Площади
A1: № | B1: Помещение | C1: Площадь, м²
B2: Цоколь
A3: 0.01 | B3: Постирочная | C3: 10.7
A4: 0.02 | B4: Лестница | C4: 10.5
A5: 0.03 | B5: Хозвход с улицы + сезонное хранение | C5: 7.8
A6: 0.04 | B6: Лобби цоколя | C6: 9
A7: 0.05 | B7: Прохладная кладовая: продукты, морозильник, напитки | C7: 12.2
A8: 0.06 | B8: Техпомещение: вода, бассейн, электрика | C8: 12.1
B9: Итого цоколь (полезная) | C9: =SUM(C3:C8) -> 62.3
B10: 1 этаж
A11: 1.01 | B11: Зал бассейна + лаунж SPA | C11: 51
A12: 1.02 | B12: Раздевалка SPA (вход из дома) | C12: 6.6
A13: 1.03 | B13: С/у SPA: WC, душ, раковина | C13: 5.1
A14: 1.04 | B14: Сауна 4–5 чел. | C14: 6.8
A15: 1.05 | B15: Кухня-гостиная | C15: 62.6
A16: 1.06 | B16: Лестница (с маршем в цоколь) | C16: 10.5
A17: 1.07 | B17: Холл | C17: 8.6
A18: 1.08 | B18: Хозяйственная кладовая | C18: 7.1
A19: 1.09 | B19: Гостевая спальня | C19: 15
A20: 1.10 | B20: Душ / WC гостевой | C20: 4.3
A21: 1.11 | B21: Тамбур-прихожая | C21: 11
A22: 1.12 | B22: Гараж 2 авто + мото | C22: 73
... A24: 1.14 | B24: Хозблок | C24: 19.7
B25: Итого 1 этаж (полезная) | C25: =SUM(C11:C24) -> 290.7
B26: 2 этаж
A27: 2.01 | B27: Игровая | C27: 16.4
A28: 2.02 | B28: Семейный санузел (ванна) | C28: 7.9
A29: 2.03 | B29: Бельевой узел: бельепровод, подъёмник | C29: 3.2
A30: 2.04 | B30: Лестница | C30: 10.5
A31: 2.05 | B31: Комната Насти | C31: 13
A32: 2.06 | B32: Мастер-гардеробная | C32: 12
A33: 2.07 | B33: Мастер-санузел | C33: 9.1
A34: 2.08 | B34: Коридор | C34: 9.1
A35: 2.09 | B35: Кабинет | C35: 17.5
A36: 2.10 | B36: Кладовая-буфер | C36: 4.9
A37: 2.11 | B37: Спальня Максима | C37: 12.8
A38: 2.12 | B38: Мастер-спальня | C38: 21.6
B39: Итого 2 этаж (полезная) | C39: =SUM(C27:C38) -> 138
B41: По наружному контуру
B42: Цоколь | C42: 80
...
